Workbook

Sheet Shipped SKU
A1: SKU | B1: Qty | C1: Error
A2: xy-s-a-wht | B2: 132 | C2: =_xlfn.CONCAT( IF(ISNA(MATCH(Ship_SKU[[#This Row],[SKU]], SKU[SKU], 0)), _xlfn.CONCAT("Missing ", Ship_SKU[[#This Row],[SKU]], " definition"), ""), IF(ISNUMBER(Ship_SKU[[#This Row],[Qty]]), "", "Quantity is not number") )
A3: xy-s-ps-wht-915 | B3: 38 | C3: =_xlfn.CONCAT( IF(ISNA(MATCH(Ship_SKU[[#This Row],[SKU]], SKU[SKU], 0)), _xlfn.CONCAT("Missing ", Ship_SKU[[#This Row],[SKU]], " definition"), ""), IF(ISNUMBER(Ship_SKU[[#This Row],[Qty]]), "", "Quantity is not number") )
A4: #36269 | B4: 11 | C4: =_xlfn.CONCAT( IF(ISNA(MATCH(Ship_SKU[[#This Row],[SKU]], SKU[SKU], 0)), _xlfn.CONCAT("Missing ", Ship_SKU[[#This Row],[SKU]], " definition"), ""), IF(ISNUMBER(Ship_SKU[[#This Row],[Qty]]), "", "Quantity is not number") )
A5: xy-hub-s-us | B5: 9 | C5: =_xlfn.CONCAT( IF(ISNA(MATCH(Ship_SKU[[#This Row],[SKU]], SKU[SKU], 0)), _xlfn.CONCAT("Missing ", Ship_SKU[[#This Row],[SKU]], " definition"), ""), IF(ISNUMBER(Ship_SKU[[#This Row],[Qty]]), "", "Quantity is not number") )
A6: xy-gw-g2x-au | B6: 4 | C6: =_xlfn.CONCAT( IF(ISNA(MATCH(Ship_SKU[[#This Row],[SKU]], SKU[SKU], 0)), _xlfn.CONCAT("Missing ", Ship_SKU[[#This Row],[SKU]], " definition"), ""), IF(ISNUMBER(Ship_SKU[[#This Row],[Qty]]), "", "Quantity is not number") )
A7: xy-hub-pr-us | B7: 4 | C7: =_xlfn.CONCAT( IF(ISNA(MATCH(Ship_SKU[[#This Row],[SKU]], SKU[SKU], 0)), _xlfn.CONCAT("Missing ", Ship_SKU[[#This Row],[SKU]], " definition"), ""), IF(ISNUMBER(Ship_SKU[[#This Row],[Qty]]), "", "Quantity is not number") )
A8: xy-hub-3p-ps-915 | B8: 2 | C8: =_xlfn.CONCAT( IF(ISNA(MATCH(Ship_SKU[[#This Row],[SKU]], SKU[SKU], 0)), _xlfn.CONCAT("Missing ", Ship_SKU[[#This Row],[SKU]], " definition"), ""), IF(ISNUMBER(Ship_SKU[[#This Row],[Qty]]), "", "Quantity is not number") )

Sheet Shipped Types
A1: REF | B1: Orders | C1: Boxes | D1: Error
A2: xy_international | B2: 3 | C2: 11 | D2: =_xlfn.CONCAT( IF(ISNA(MATCH(Ship_Type[[#This Row],[REF]], Type[REF], 0)), _xlfn.CONCAT("Missing ", Ship_Type[[#This Row],[REF]], " definition"), ""), IF(ISNUMBER(Ship_Type[[#This Row],[Orders]]), "", "Quantity is not number") )

Sheet Rates
A1: SAP Code | B1: Name | C1: Rate | D1: Orders | E1: Boxes | F1: Shipped | G1: Kitted | H1: Commissioned | I1: Qty | J1: Cost | K1: Error
A2: 1200108 | B2: Labour - Labour Rate Weekday | C2: 110 | D2: =SUMIF(Type[Ship Code], Rate[[#This Row],[SAP Code]], Type[Ship Qty]) -> 0 | E2: =SUMIF(Type[Box Code], Rate[[#This Row],[SAP Code]], Type[Box Qty]) -> 0 | F2: =SUMIF(SKU[Ship Code], Rate[[#This Row],[SAP Code]], SKU[Ship Qty]) -> 0 | G2: =SUMIF(SKU[Kit Code], Rate[[#This Row],[SAP Code]], SKU[Kit Qty]) -> 0 | H2: =SUMIF(SKU[Commission Code], Rate[[#This Row],[SAP Code]], SKU[Ship Qty]) -> 0 | I2: =SUM(Rate[[#This Row],[Orders]:[Commissioned]]) -> 0 | J2: =Rate[[#This Row],[Rate]]*Rate[[#This Row],[Qty]] -> 0 | K2: =IF(ISNA(MATCH(Rate[[#This Row],[SAP Code]], Summary!A:A, 0)), _xlfn.CONCAT("Missing ", Rate[[#This Row],[SAP Code]], " in summary"), "")
A3: 1200109 | B3: API Management | C3: 180 | D3: =SUMIF(Type[Ship Code], Rate[[#This Row],[SAP Code]], Type[Ship Qty]) -> 0 | E3: =SUMIF(Type[Box Code], Rate[[#This Row],[SAP Code]], Type[Box Qty]) -> 0 | F3: =SUMIF(SKU[Ship Code], Rate[[#This Row],[SAP Code]], SKU[Ship Qty]) -> 0 | G3: =SUMIF(SKU[Kit Code], Rate[[#This Row],[SAP Code]], SKU[Kit Qty]) -> 0 | H3: =SUMIF(SKU[Commission Code], Rate[[#This Row],[SAP Code]], SKU[Ship Qty]) -> 0 | I3: =SUM(Rate[[#This Row],[Orders]:[Commissioned]]) -> 0 | J3: =Rate[[#This Row],[Rate]]*Rate[[#This Row],[Qty]] -> 0 | K3: =IF(ISNA(MATCH(Rate[[#This Row],[SAP Code]], Summary!A:A, 0)), _xlfn.CONCAT("Missing ", Rate[[#This Row],[SAP Code]], " in summary"), "")
A4: 4002237 | B4: Dropship - Per article fee (International) | C4: 5.49 | D4: =SUMIF(Type[Ship Code], Rate[[#This Row],[SAP Code]], Type[Ship Qty]) -> 0 | E4: =SUMIF(Type[Box Code], Rate[[#This Row],[SAP Code]], Type[Box Qty]) -> 11 | F4: =SUMIF(SKU[Ship Code], Rate[[#This Row],[SAP Code]], SKU[Ship Qty]) -> 0 | G4: =SUMIF(SKU[Kit Code], Rate[[#This Row],[SAP Code]], SKU[Kit Qty]) -> 0 | H4: =SUMIF(SKU[Commission Code], Rate[[#This Row],[SAP Code]], SKU[Ship Qty]) -> 0 | I4: =SUM(Rate[[#This Row],[Orders]:[Commissioned]]) -> 11 | J4: =Rate[[#This Row],[Rate]]*Rate[[#This Row],[Qty]] -> 60.39 | K4: =IF(ISNA(MATCH(Rate[[#This Row],[SAP Code]], Summary!A:A, 0)), _xlfn.CONCAT("Missing ", Rate[[#This Row],[SAP Code]], " in summary"), "")
A5: 4002238 | B5: Dropship - Per article fee (Australia-wide) | C5: 3.28 | D5: =SUMIF(Type[Ship Code], Rate[[#This Row],[SAP Code]], Type[Ship Qty]) -> 0 | E5: =SUMIF(Type[Box Code], Rate[[#This Row],[SAP Code]], Type[Box Qty]) -> 0 | F5: =SUMIF(SKU[Ship Code], Rate[[#This Row],[SAP Code]], SKU[Ship Qty]) -> 0 | G5: =SUMIF(SKU[Kit Code], Rate[[#This Row],[SAP Code]], SKU[Kit Qty]) -> 0 | H5: =SUMIF(SKU[Commission Code], Rate[[#This Row],[SAP Code]], SKU[Ship Qty]) -> 0 | I5: =SUM(Rate[[#This Row],[Orders]:[Commissioned]]) -> 0 | J5: =Rate[[#This Row],[Rate]]*Rate[[#This Row],[Qty]] -> 0 | K5: =IF(ISNA(MATCH(Rate[[#This Row],[SAP Code]], Summary!A:A, 0)), _xlfn.CONCAT("Missing ", Rate[[#This Row],[SAP Code]], " in summary"), "")
A6: 4002239 | B6: Dropship - Per item fee | C6: 2.48 | D6: =SUMIF(Type[Ship Code], Rate[[#This Row],[SAP Code]], Type[Ship Qty]) -> 0 | E6: =SUMIF(Type[Box Code], Rate[[#This Row],[SAP Code]], Type[Box Qty]) -> 0 | F6: =SUMIF(SKU[Ship Code], Rate[[#This Row],[SAP Code]], SKU[Ship Qty]) -> 189 | G6: =SUMIF(SKU[Kit Code], Rate[[#This Row],[SAP Code]], SKU[Kit Qty]) -> 0 | H6: =SUMIF(SKU[Commission Code], Rate[[#This Row],[SAP Code]], SKU[Ship Qty]) -> 0 | I6: =SUM(Rate[[#This Row],[Orders]:[Commissioned]]) -> 189 | J6: =Rate[[#This Row],[Rate]]*Rate[[#This Row],[Qty]] -> 468.72 | K6: =IF(ISNA(MATCH(Rate[[#This Row],[SAP Code]], Summary!A:A, 0)), _xlfn.CONCAT("Missing ", Rate[[#This Row],[SAP Code]], " in summary"), "")
A7: 4002240 | B7: Kitting - Per part fee | C7: 1.89 | D7: =SUMIF(Type[Ship Code], Rate[[#This Row],[SAP Code]], Type[Ship Qty]) -> 0 | E7: =SUMIF(Type[Box Code], Rate[[#This Row],[SAP Code]], Type[Box Qty]) -> 0 | F7: =SUMIF(SKU[Ship Code], Rate[[#This Row],[SAP Code]], SKU[Ship Qty]) -> 0 | G7: =SUMIF(SKU[Kit Code], Rate[[#This Row],[SAP Code]], SKU[Kit Qty]) -> 157 | H7: =SUMIF(SKU[Commission Code], Rate[[#This Row],[SAP Code]], SKU[Ship Qty]) -> 0 | I7: =SUM(Rate[[#This Row],[Orders]:[Commissioned]]) -> 157 | J7: =Rate[[#This Row],[Rate]]*Rate[[#This Row],[Qty]] -> 296.73 | K7: =IF(ISNA(MATCH(Rate[[#This Row],[SAP Code]], Summary!A:A, 0)), _xlfn.CONCAT("Missing ", Rate[[#This Row],[SAP Code]], " in summary"), "")
A8: 4002242 | B8: Commissioning - Presence HUB | C8: 10.99 | D8: =SUMIF(Type[Ship Code], Rate[[#This Row],[SAP Code]], Type[Ship Qty]) -> 0 | E8: =SUMIF(Type[Box Code], Rate[[#This Row],[SAP Code]], Type[Box Qty]) -> 0 | F8: =SUMIF(SKU[Ship Code], Rate[[#This Row],[SAP Code]], SKU[Ship Qty]) -> 0 | G8: =SUMIF(SKU[Kit Code], Rate[[#This Row],[SAP Code]], SKU[Kit Qty]) -> 0 | H8: =SUMIF(SKU[Commission Code], Rate[[#This Row],[SAP Code]], SKU[Ship Qty]) -> 2 | I8: =SUM(Rate[[#This Row],[Orders]:[Commissioned]]) -> 2 | J8: =Rate[[#This Row],[Rate]]*Rate[[#This Row],[Qty]] -> 21.98 | K8: =IF(ISNA(MATCH(Rate[[#This Row],[SAP Code]], Summary!A:A, 0)), _xlfn.CONCAT("Missing ", Rate[[#This Row],[SAP Code]], " in summary"), "")
A9: 4002243 | B9: Commissioning - Presence Sensor | C9: 2.95 | D9: =SUMIF(Type[Ship Code], Rate[[#This Row],[SAP Code]], Type[Ship Qty]) -> 0 | E9: =SUMIF(Type[Box Code], Rate[[#This Row],[SAP Code]], Type[Box Qty]) -> 0 | F9: =SUMIF(SKU[Ship Code], Rate[[#This Row],[SAP Code]], SKU[Ship Qty]) -> 0 | G9: =SUMIF(SKU[Kit Code], Rate[[#This Row],[SAP Code]], SKU[Kit Qty]) -> 0 | H9: =SUMIF(SKU[Commission Code], Rate[[#This Row],[SAP Code]], SKU[Ship Qty]) -> 38 | I9: =SUM(Rate[[#This Row],[Orders]:[Commissioned]]) -> 38 | J9: =Rate[[#This Row],[Rate]]*Rate[[#This Row],[Qty]] -> 112.1 | K9: =IF(ISNA(MATCH(Rate[[#This Row],[SAP Code]], Summary!A:A, 0)), _xlfn.CONCAT("Missing ", Rate[[#This Row],[SAP Code]], " in summary"), "")
A10: 4002244 | B10: RTS - Per Order Fee | C10: 5.57 | D10: =SUMIF(Type[Ship Code], Rate[[#This Row],[SAP Code]], Type[Ship Qty]) -> 0 | E10: =SUMIF(Type[Box Code], Rate[[#This Row],[SAP Code]], Type[Box Qty]) -> 0 | F10: =SUMIF(SKU[Ship Code], Rate[[#This Row],[SAP Code]], SKU[Ship Qty]) -> 0 | G10: =SUMIF(SKU[Kit Code], Rate[[#This Row],[SAP Code]], SKU[Kit Qty]) -> 0 | H10: =SUMIF(SKU[Commission Code], Rate[[#This Row],[SAP Code]], SKU[Ship Qty]) -> 0 | I10: =SUM(Rate[[#This Row],[Orders]:[Commissioned]]) -> 0 | J10: =Rate[[#This Row],[Rate]]*Rate[[#This Row],[Qty]] -> 0 | K10: =IF(ISNA(MATCH(Rate[[#This Row],[SAP Code]], Summary!A:A, 0)), _xlfn.CONCAT("Missing ", Rate[[#This Row],[SAP Code]], " in summary"), "")
A11: 4002276 | B11: Commissioning - Gateway Primary | C11: 14.67 | D11: =SUMIF(Type[Ship Code], Rate[[#This Row],[SAP Code]], Type[Ship Qty]) -> 0 | E11: =SUMIF(Type[Box Code], Rate[[#This Row],[SAP Code]], Type[Box Qty]) -> 0 | F11: =SUMIF(SKU[Ship Code], Rate[[#This Row],[SAP Code]], SKU[Ship Qty]) -> 0 | G11: =SUMIF(SKU[Kit Code], Rate[[#This Row],[SAP Code]], SKU[Kit Qty]) -> 0 | H11: =SUMIF(SKU[Commission Code], Rate[[#This Row],[SAP Code]], SKU[Ship Qty]) -> 0 | I11: =SUM(Rate[[#This Row],[Orders]:[Commissioned]]) -> 0 | J11: =Rate[[#This Row],[Rate]]*Rate[[#This Row],[Qty]] -> 0 | K11: =IF(ISNA(MATCH(Rate[[#This Row],[SAP Code]], Summary!A:A, 0)), _xlfn.CONCAT("Missing ", Rate[[#This Row],[SAP Code]], " in summary"), "")
A12: 4002277 | B12: Commissioning – Router AU with Telstra SIM | C12: 13.89 | D12: =SUMIF(Type[Ship Code], Rate[[#This Row],[SAP Code]], Type[Ship Qty]) -> 0 | E12: =SUMIF(Type[Box Code], Rate[[#This Row],[SAP Code]], Type[Box Qty]) -> 0 | F12: =SUMIF(SKU[Ship Code], Rate[[#This Row],[SAP Code]], SKU[Ship Qty]) -> 0 | G12: =SUMIF(SKU[Kit Code], Rate[[#This Row],[SAP Code]], SKU[Kit Qty]) -> 0 | H12: =SUMIF(SKU[Commission Code], Rate[[#This Row],[SAP Code]], SKU[Ship Qty]) -> 0 | I12: =SUM(Rate[[#This Row],[Orders]:[Commissioned]]) -> 0 | J12: =Rate[[#This Row],[Rate]]*Rate[[#This Row],[Qty]] -> 0 | K12: =IF(ISNA(MATCH(Rate[[#This Row],[SAP Code]], Summary!A:A, 0)), _xlfn.CONCAT("Missing ", Rate[[#This Row],[SAP Code]], " in summary"), "")
A13: Disbursement | B13: Disbursement Fee | C13: 1 | D13: =SUMIF(Type[Ship Code], Rate[[#This Row],[SAP Code]], Type[Ship Qty]) -> 0 | E13: =SUMIF(Type[Box Code], Rate[[#This Row],[SAP Code]], Type[Box Qty]) -> 0 | F13: =SUMIF(SKU[Ship Code], Rate[[#This Row],[SAP Code]], SKU[Ship Qty]) -> 0 | G13: =SUMIF(SKU[Kit Code], Rate[[#This Row],[SAP Code]], SKU[Kit Qty]) -> 0 | H13: =SUMIF(SKU[Commission Code], Rate[[#This Row],[SAP Code]], SKU[Ship Qty]) -> 0 | I13: =SUM(Rate[[#This Row],[Orders]:[Commissioned]]) -> 0 | J13: =Rate[[#This Row],[Rate]]*Rate[[#This Row],[Qty]] -> 0 | K13: =IF(ISNA(MATCH(Rate[[#This Row],[SAP Code]], Summary!A:A, 0)), _xlfn.CONCAT("Missing ", Rate[[#This Row],[SAP Code]], " in summary"), "")
A14: Freight | B14: Sub-Account Freight Costs | C14: 1 | D14: =SUMIF(Type[Ship Code], Rate[[#This Row],[SAP Code]], Type[Ship Qty]) -> 0 | E14: =SUMIF(Type[Box Code], Rate[[#This Row],[SAP Code]], Type[Box Qty]) -> 0 | F14: =SUMIF(SKU[Ship Code], Rate[[#This Row],[SAP Code]], SKU[Ship Qty]) -> 0 | G14: =SUMIF(SKU[Kit Code], Rate[[#This Row],[SAP Code]], SKU[Kit Qty]) -> 0 | H14: =SUMIF(SKU[Commission Code], Rate[[#This Row],[SAP Code]], SKU[Ship Qty]) -> 0 | I14: =SUM(Rate[[#This Row],[Orders]:[Commissioned]]) -> 0 | J14: =Rate[[#This Row],[Rate]]*Rate[[#This Row],[Qty]] -> 0 | K14: =IF(ISNA(MATCH(Rate[[#This Row],[SAP Code]], Summary!A:A, 0)), _xlfn.CONCAT("Missing ", Rate[[#This Row],[SAP Code]], " in summary"), "")
A15: Storage | B15: Pallet Storage | C15: 6.2 | D15: =SUMIF(Type[Ship Code], Rate[[#This Row],[SAP Code]], Type[Ship Qty]) -> 0 | E15: =SUMIF(Type[Box Code], Rate[[#This Row],[SAP Code]], Type[Box Qty]) -> 0 | F15: =SUMIF(SKU[Ship Code], Rate[[#This Row],[SAP Code]], SKU[Ship Qty]) -> 0 | G15: =SUMIF(SKU[Kit Code], Rate[[#This Row],[SAP Code]], SKU[Kit Qty]) -> 0 | H15: =SUMIF(SKU[Commission Code], Rate[[#This Row],[SAP Code]], SKU[Ship Qty]) -> 0 | I15: =SUM(Rate[[#This Row],[Orders]:[Commissioned]]) -> 0 | J15: =Rate[[#This Row],[Rate]]*Rate[[#This Row],[Qty]] -> 0 | K15: =IF(ISNA(MATCH(Rate[[#This Row],[SAP Code]], Summary!A:A, 0)), _xlfn.CONCAT("Missing ", Rate[[#This Row],[SAP Code]], " in summary"), "")
A16: Adhoc | B16: Adhoc Fees | C16: 1 | D16: =SUMIF(Type[Ship Code], Rate[[#This Row],[SAP Code]], Type[Ship Qty]) -> 0 | E16: =SUMIF(Type[Box Code], Rate[[#This Row],[SAP Code]], Type[Box Qty]) -> 0 | F16: =SUMIF(SKU[Ship Code], Rate[[#This Row],[SAP Code]], SKU[Ship Qty]) -> 0 | G16: =SUMIF(SKU[Kit Code], Rate[[#This Row],[SAP Code]], SKU[Kit Qty]) -> 0 | H16: =SUMIF(SKU[Commission Code], Rate[[#This Row],[SAP Code]], SKU[Ship Qty]) -> 0 | I16: =SUM(Rate[[#This Row],[Orders]:[Commissioned]]) -> 0 | J16: =Rate[[#This Row],[Rate]]*Rate[[#This Row],[Qty]] -> 0 | K16: =IF(ISNA(MATCH(Rate[[#This Row],[SAP Code]], Summary!A:A, 0)), _xlfn.CONCAT("Missing ", Rate[[#This Row],[SAP Code]], " in summary"), "")
I18: Total | J18: =SUM(Rate[Cost]) -> 959.92

Sheet SKU Summary
A1: SKU | B1: Name | C1: Ship Code | D1: Ship Qty | E1: Ship Cost | F1: Kit Code | G1: Kit Items | H1: Kit Qty | I1: Kit Cost | J1: Commission Code | K1: Comission Cost | L1: Total | M1: Error
A2: #36269 | B2: XY Outer Box | D2: =SUMIF(Ship_SKU[SKU], SKU[[#This Row],[SKU]], Ship_SKU[Qty]) -> 11 | E2: =IF(SKU[[#This Row],[Ship Code]]="", 0, VLOOKUP(SKU[[#This Row],[Ship Code]], Rate[], 3, FALSE)*SKU[[#This Row],[Ship Qty]]) -> 0 | H2: =SKU[[#This Row],[Ship Qty]]*SKU[[#This Row],[Kit Items]] -> 0 | I2: =IF(SKU[[#This Row],[Kit Code]]="", 0, VLOOKUP(SKU[[#This Row],[Kit Code]], Rate[], 3, FALSE)*SKU[[#This Row],[Kit Qty]]) -> 0 | K2: =IF(SKU[[#This Row],[Commission Code]]="", 0, VLOOKUP(SKU[[#This Row],[Commission Code]], Rate[], 3, FALSE)*SKU[[#This Row],[Ship Qty]]) -> 0 | L2: =SKU[[#This Row],[Ship Cost]]+SKU[[#This Row],[Kit Cost]]+SKU[[#This Row],[Comission Cost]] -> 0 | M2: =IF(OR(ISNA(SKU[[#This Row],[Ship Cost]]), ISNA(SKU[[#This Row],[Kit Cost]]), ISNA(SKU[[#This Row],[Comission Cost]])), "Error Accessing SAP Rate", "")
A3: xy-c-slnk | B3: SenseLink PoE Converter (passive PoE) | C3: 4002239 | D3: =SUMIF(Ship_SKU[SKU], SKU[[#This Row],[SKU]], Ship_SKU[Qty]) -> 0 | E3: =IF(SKU[[#This Row],[Ship Code]]="", 0, VLOOKUP(SKU[[#This Row],[Ship Code]], Rate[], 3, FALSE)*SKU[[#This Row],[Ship Qty]]) -> 0 | H3: =SKU[[#This Row],[Ship Qty]]*SKU[[#This Row],[Kit Items]] -> 0 | I3: =IF(SKU[[#This Row],[Kit Code]]="", 0, VLOOKUP(SKU[[#This Row],[Kit Code]], Rate[], 3, FALSE)*SKU[[#This Row],[Kit Qty]]) -> 0 | K3: =IF(SKU[[#This Row],[Commission Code]]="", 0, VLOOKUP(SKU[[#This Row],[Commission Code]], Rate[], 3, FALSE)*SKU[[#This Row],[Ship Qty]]) -> 0 | L3: =SKU[[#This Row],[Ship Cost]]+SKU[[#This Row],[Kit Cost]]+SKU[[#This Row],[Comission Cost]] -> 0 | M3: =IF(OR(ISNA(SKU[[#This Row],[Ship Cost]]), ISNA(SKU[[#This Row],[Kit Cost]]), ISNA(SKU[[#This Row],[Comission Cost]])), "Error Accessing SAP Rate", "")
A4: xy-gw-g2a-au | B4: XY Gateway Midspan Injector (Gen 2) 106-1003 AU | C4: 4002239 | D4: =SUMIF(Ship_SKU[SKU], SKU[[#This Row],[SKU]], Ship_SKU[Qty]) -> 0 | E4: =IF(SKU[[#This Row],[Ship Code]]="", 0, VLOOKUP(SKU[[#This Row],[Ship Code]], Rate[], 3, FALSE)*SKU[[#This Row],[Ship Qty]]) -> 0 | F4: 4002240 | G4: 1 | H4: =SKU[[#This Row],[Ship Qty]]*SKU[[#This Row],[Kit Items]] -> 0 | I4: =IF(SKU[[#This Row],[Kit Code]]="", 0, VLOOKUP(SKU[[#This Row],[Kit Code]], Rate[], 3, FALSE)*SKU[[#This Row],[Kit Qty]]) -> 0 | K4: =IF(SKU[[#This Row],[Commission Code]]="", 0, VLOOKUP(SKU[[#This Row],[Commission Code]], Rate[], 3, FALSE)*SKU[[#This Row],[Ship Qty]]) -> 0 | L4: =SKU[[#This Row],[Ship Cost]]+SKU[[#This Row],[Kit Cost]]+SKU[[#This Row],[Comission Cost]] -> 0 | M4: =IF(OR(ISNA(SKU[[#This Row],[Ship Cost]]), ISNA(SKU[[#This Row],[Kit Cost]]), ISNA(SKU[[#This Row],[Comission Cost]])), "Error Accessing SAP Rate", "")
A5: xy-gw-g2a-eu | B5: XY Gateway Midspan Injector (Gen 2) 106-1003 EU | C5: 4002239 | D5: =SUMIF(Ship_SKU[SKU], SKU[[#This Row],[SKU]], Ship_SKU[Qty]) -> 0 | E5: =IF(SKU[[#This Row],[Ship Code]]="", 0, VLOOKUP(SKU[[#This Row],[Ship Code]], Rate[], 3, FALSE)*SKU[[#This Row],[Ship Qty]]) -> 0 | F5: 4002240 | G5: 1 | H5: =SKU[[#This Row],[Ship Qty]]*SKU[[#This Row],[Kit Items]] -> 0 | I5: =IF(SKU[[#This Row],[Kit Code]]="", 0, VLOOKUP(SKU[[#This Row],[Kit Code]], Rate[], 3, FALSE)*SKU[[#This Row],[Kit Qty]]) -> 0 | K5: =IF(SKU[[#This Row],[Commission Code]]="", 0, VLOOKUP(SKU[[#This Row],[Commission Code]], Rate[], 3, FALSE)*SKU[[#This Row],[Ship Qty]]) -> 0 | L5: =SKU[[#This Row],[Ship Cost]]+SKU[[#This Row],[Kit Cost]]+SKU[[#This Row],[Comission Cost]] -> 0 | M5: =IF(OR(ISNA(SKU[[#This Row],[Ship Cost]]), ISNA(SKU[[#This Row],[Kit Cost]]), ISNA(SKU[[#This Row],[Comission Cost]])), "Error Accessing SAP Rate", "")
A6: xy-gw-g2a-in | B6: XY Gateway Midspan Injector (Gen 2) 106-1003 IN | C6: 4002239 | D6: =SUMIF(Ship_SKU[SKU], SKU[[#This Row],[SKU]], Ship_SKU[Qty]) -> 0 | E6: =IF(SKU[[#This Row],[Ship Code]]="", 0, VLOOKUP(SKU[[#This Row],[Ship Code]], Rate[], 3, FALSE)*SKU[[#This Row],[Ship Qty]]) -> 0 | F6: 4002240 | G6: 1 | H6: =SKU[[#This Row],[Ship Qty]]*SKU[[#This Row],[Kit Items]] -> 0 | I6: =IF(SKU[[#This Row],[Kit Code]]="", 0, VLOOKUP(SKU[[#This Row],[Kit Code]], Rate[], 3, FALSE)*SKU[[#This Row],[Kit Qty]]) -> 0 | K6: =IF(SKU[[#This Row],[Commission Code]]="", 0, VLOOKUP(SKU[[#This Row],[Commission Code]], Rate[], 3, FALSE)*SKU[[#This Row],[Ship Qty]]) -> 0 | L6: =SKU[[#This Row],[Ship Cost]]+SKU[[#This Row],[Kit Cost]]+SKU[[#This Row],[Comission Cost]] -> 0 | M6: =IF(OR(ISNA(SKU[[#This Row],[Ship Cost]]), ISNA(SKU[[#This Row],[Kit Cost]]), ISNA(SKU[[#This Row],[Comission Cost]])), "Error Accessing SAP Rate", "")
A7: xy-gw-g2-au | B7: XY Gateway (Gen 2) 106-1001-241 AU | C7: 4002239 | D7: =SUMIF(Ship_SKU[SKU], SKU[[#This Row],[SKU]], Ship_SKU[Qty]) -> 0 | E7: =IF(SKU[[#This Row],[Ship Code]]="", 0, VLOOKUP(SKU[[#This Row],[Ship Code]], Rate[], 3, FALSE)*SKU[[#This Row],[Ship Qty]]) -> 0 | F7: 4002240 | G7: 7 | H7: =SKU[[#This Row],[Ship Qty]]*SKU[[#This Row],[Kit Items]] -> 0 | I7: =IF(SKU[[#This Row],[Kit Code]]="", 0, VLOOKUP(SKU[[#This Row],[Kit Code]], Rate[], 3, FALSE)*SKU[[#This Row],[Kit Qty]]) -> 0 | J7: 4002276 | K7: =IF(SKU[[#This Row],[Commission Code]]="", 0, VLOOKUP(SKU[[#This Row],[Commission Code]], Rate[], 3, FALSE)*SKU[[#This Row],[Ship Qty]]) -> 0 | L7: =SKU[[#This Row],[Ship Cost]]+SKU[[#This Row],[Kit Cost]]+SKU[[#This Row],[Comission Cost]] -> 0 | M7: =IF(OR(ISNA(SKU[[#This Row],[Ship Cost]]), ISNA(SKU[[#This Row],[Kit Cost]]), ISNA(SKU[[#This Row],[Comission Cost]])), "Error Accessing SAP Rate", "")
A8: xy-gw-g2a-uk | B8: XY Gateway Midspan Injector (Gen 2) 106-1003 UK | C8: 4002239 | D8: =SUMIF(Ship_SKU[SKU], SKU[[#This Row],[SKU]], Ship_SKU[Qty]) -> 0 | E8: =IF(SKU[[#This Row],[Ship Code]]="", 0, VLOOKUP(SKU[[#This Row],[Ship Code]], Rate[], 3, FALSE)*SKU[[#This Row],[Ship Qty]]) -> 0 | F8: 4002240 | G8: 1 | H8: =SKU[[#This Row],[Ship Qty]]*SKU[[#This Row],[Kit Items]] -> 0 | I8: =IF(SKU[[#This Row],[Kit Code]]="", 0, VLOOKUP(SKU[[#This Row],[Kit Code]], Rate[], 3, FALSE)*SKU[[#This Row],[Kit Qty]]) -> 0 | K8: =IF(SKU[[#This Row],[Commission Code]]="", 0, VLOOKUP(SKU[[#This Row],[Commission Code]], Rate[], 3, FALSE)*SKU[[#This Row],[Ship Qty]]) -> 0 | L8: =SKU[[#This Row],[Ship Cost]]+SKU[[#This Row],[Kit Cost]]+SKU[[#This Row],[Comission Cost]] -> 0 | M8: =IF(OR(ISNA(SKU[[#This Row],[Ship Cost]]), ISNA(SKU[[#This Row],[Kit Cost]]), ISNA(SKU[[#This Row],[Comission Cost]])), "Error Accessing SAP Rate", "")
A9: xy-gw-g2a-us | B9: XY Gateway Midspan Injector (Gen 2) 106-1003 US | C9: 4002239 | D9: =SUMIF(Ship_SKU[SKU], SKU[[#This Row],[SKU]], Ship_SKU[Qty]) -> 0 | E9: =IF(SKU[[#This Row],[Ship Code]]="", 0, VLOOKUP(SKU[[#This Row],[Ship Code]], Rate[], 3, FALSE)*SKU[[#This Row],[Ship Qty]]) -> 0 | F9: 4002240 | G9: 1 | H9: =SKU[[#This Row],[Ship Qty]]*SKU[[#This Row],[Kit Items]] -> 0 | I9: =IF(SKU[[#This Row],[Kit Code]]="", 0, VLOOKUP(SKU[[#This Row],[Kit Code]], Rate[], 3, FALSE)*SKU[[#This Row],[Kit Qty]]) -> 0 | K9: =IF(SKU[[#This Row],[Commission Code]]="", 0, VLOOKUP(SKU[[#This Row],[Commission Code]], Rate[], 3, FALSE)*SKU[[#This Row],[Ship Qty]]) -> 0 | L9: =SKU[[#This Row],[Ship Cost]]+SKU[[#This Row],[Kit Cost]]+SKU[[#This Row],[Comission Cost]] -> 0 | M9: =IF(OR(ISNA(SKU[[#This Row],[Ship Cost]]), ISNA(SKU[[#This Row],[Kit Cost]]), ISNA(SKU[[#This Row],[Comission Cost]])), "Error Accessing SAP Rate", "")
A10: xy-gw-g2-eu | B10: XY Gateway (Gen 2) 106-1001-241 EU | C10: 4002239 | D10: =SUMIF(Ship_SKU[SKU], SKU[[#This Row],[SKU]], Ship_SKU[Qty]) -> 0 | E10: =IF(SKU[[#This Row],[Ship Code]]="", 0, VLOOKUP(SKU[[#This Row],[Ship Code]], Rate[], 3, FALSE)*SKU[[#This Row],[Ship Qty]]) -> 0 | F10: 4002240 | G10: 7 | H10: =SKU[[#This Row],[Ship Qty]]*SKU[[#This Row],[Kit Items]] -> 0 | I10: =IF(SKU[[#This Row],[Kit Code]]="", 0, VLOOKUP(SKU[[#This Row],[Kit Code]], Rate[], 3, FALSE)*SKU[[#This Row],[Kit Qty]]) -> 0 | J10: 4002276 | K10: =IF(SKU[[#This Row],[Commission Code]]="", 0, VLOOKUP(SKU[[#This Row],[Commission Code]], Rate[], 3, FALSE)*SKU[[#This Row],[Ship Qty]]) -> 0 | L10: =SKU[[#This Row],[Ship Cost]]+SKU[[#This Row],[Kit Cost]]+SKU[[#This Row],[Comission Cost]] -> 0 | M10: =IF(OR(ISNA(SKU[[#This Row],[Ship Cost]]), ISNA(SKU[[#This Row],[Kit Cost]]), ISNA(SKU[[#This Row],[Comission Cost]])), "Error Accessing SAP Rate", "")
A11: xy-gw-g2-gb | B11: XY Gateway (Gen 2) 106-1001-241 UK | C11: 4002239 | D11: =SUMIF(Ship_SKU[SKU], SKU[[#This Row],[SKU]], Ship_SKU[Qty]) -> 0 | E11: =IF(SKU[[#This Row],[Ship Code]]="", 0, VLOOKUP(SKU[[#This Row],[Ship Code]], Rate[], 3, FALSE)*SKU[[#This Row],[Ship Qty]]) -> 0 | F11: 4002240 | G11: 7 | H11: =SKU[[#This Row],[Ship Qty]]*SKU[[#This Row],[Kit Items]] -> 0 | I11: =IF(SKU[[#This Row],[Kit Code]]="", 0, VLOOKUP(SKU[[#This Row],[Kit Code]], Rate[], 3, FALSE)*SKU[[#This Row],[Kit Qty]]) -> 0 | J11: 4002276 | K11: =IF(SKU[[#This Row],[Commission Code]]="", 0, VLOOKUP(SKU[[#This Row],[Commission Code]], Rate[], 3, FALSE)*SKU[[#This Row],[Ship Qty]]) -> 0 | L11: =SKU[[#This Row],[Ship Cost]]+SKU[[#This Row],[Kit Cost]]+SKU[[#This Row],[Comission Cost]] -> 0 | M11: =IF(OR(ISNA(SKU[[#This Row],[Ship Cost]]), ISNA(SKU[[#This Row],[Kit Cost]]), ISNA(SKU[[#This Row],[Comission Cost]])), "Error Accessing SAP Rate", "")
A12: xy-gw-g2-in | B12: XY Gateway (Gen 2) 106-1001-200 IN | C12: 4002239 | D12: =SUMIF(Ship_SKU[SKU], SKU[[#This Row],[SKU]], Ship_SKU[Qty]) -> 0 | E12: =IF(SKU[[#This Row],[Ship Code]]="", 0, VLOOKUP(SKU[[#This Row],[Ship Code]], Rate[], 3, FALSE)*SKU[[#This Row],[Ship Qty]]) -> 0 | F12: 4002240 | G12: 7 | H12: =SKU[[#This Row],[Ship Qty]]*SKU[[#This Row],[Kit Items]] -> 0 | I12: =IF(SKU[[#This Row],[Kit Code]]="", 0, VLOOKUP(SKU[[#This Row],[Kit Code]], Rate[], 3, FALSE)*SKU[[#This Row],[Kit Qty]]) -> 0 | J12: 4002276 | K12: =IF(SKU[[#This Row],[Commission Code]]="", 0, VLOOKUP(SKU[[#This Row],[Commission Code]], Rate[], 3, FALSE)*SKU[[#This Row],[Ship Qty]]) -> 0 | L12: =SKU[[#This Row],[Ship Cost]]+SKU[[#This Row],[Kit Cost]]+SKU[[#This Row],[Comission Cost]] -> 0 | M12: =IF(OR(ISNA(SKU[[#This Row],[Ship Cost]]), ISNA(SKU[[#This Row],[Kit Cost]]), ISNA(SKU[[#This Row],[Comission Cost]])), "Error Accessing SAP Rate", "")
A13: xy-gw-g2-my | B13: XY Gateway (Gen 2) 106-1001-241 MY | C13: 4002239 | D13: =SUMIF(Ship_SKU[SKU], SKU[[#This Row],[SKU]], Ship_SKU[Qty]) -> 0 | E13: =IF(SKU[[#This Row],[Ship Code]]="", 0, VLOOKUP(SKU[[#This Row],[Ship Code]], Rate[], 3, FALSE)*SKU[[#This Row],[Ship Qty]]) -> 0 | F13: 4002240 | G13: 7 | H13: =SKU[[#This Row],[Ship Qty]]*SKU[[#This Row],[Kit Items]] -> 0 | I13: =IF(SKU[[#This Row],[Kit Code]]="", 0, VLOOKUP(SKU[[#This Row],[Kit Code]], Rate[], 3, FALSE)*SKU[[#This Row],[Kit Qty]]) -> 0 | J13: 4002276 | K13: =IF(SKU[[#This Row],[Commission Code]]="", 0, VLOOKUP(SKU[[#This Row],[Commission Code]], Rate[], 3, FALSE)*SKU[[#This Row],[Ship Qty]]) -> 0 | L13: =SKU[[#This Row],[Ship Cost]]+SKU[[#This Row],[Kit Cost]]+SKU[[#This Row],[Comission Cost]] -> 0 | M13: =IF(OR(ISNA(SKU[[#This Row],[Ship Cost]]), ISNA(SKU[[#This Row],[Kit Cost]]), ISNA(SKU[[#This Row],[Comission Cost]])), "Error Accessing SAP Rate", "")
A14: xy-gw-g2-nz | B14: XY Gateway (Gen 2) 106-1001-241 NZ | C14: 4002239 | D14: =SUMIF(Ship_SKU[SKU], SKU[[#This Row],[SKU]], Ship_SKU[Qty]) -> 0 | E14: =IF(SKU[[#This Row],[Ship Code]]="", 0, VLOOKUP(SKU[[#This Row],[Ship Code]], Rate[], 3, FALSE)*SKU[[#This Row],[Ship Qty]]) -> 0 | F14: 4002240 | G14: 7 | H14: =SKU[[#This Row],[Ship Qty]]*SKU[[#This Row],[Kit Items]] -> 0 | I14: =IF(SKU[[#This Row],[Kit Code]]="", 0, VLOOKUP(SKU[[#This Row],[Kit Code]], Rate[], 3, FALSE)*SKU[[#This Row],[Kit Qty]]) -> 0 | J14: 4002276 | K14: =IF(SKU[[#This Row],[Commission Code]]="", 0, VLOOKUP(SKU[[#This Row],[Commission Code]], Rate[], 3, FALSE)*SKU[[#This Row],[Ship Qty]]) -> 0 | L14: =SKU[[#This Row],[Ship Cost]]+SKU[[#This Row],[Kit Cost]]+SKU[[#This Row],[Comission Cost]] -> 0 | M14: =IF(OR(ISNA(SKU[[#This Row],[Ship Cost]]), ISNA(SKU[[#This Row],[Kit Cost]]), ISNA(SKU[[#This Row],[Comission Cost]])), "Error Accessing SAP Rate", "")
A15: xy-gw-g2-us | B15: XY Gateway (Gen 2) 106-1001-241 US | C15: 4002239 | D15: =SUMIF(Ship_SKU[SKU], SKU[[#This Row],[SKU]], Ship_SKU[Qty]) -> 0 | E15: =IF(SKU[[#This Row],[Ship Code]]="", 0, VLOOKUP(SKU[[#This Row],[Ship Code]], Rate[], 3, FALSE)*SKU[[#This Row],[Ship Qty]]) -> 0 | F15: 4002240 | G15: 7 | H15: =SKU[[#This Row],[Ship Qty]]*SKU[[#This Row],[Kit Items]] -> 0 | I15: =IF(SKU[[#This Row],[Kit Code]]="", 0, VLOOKUP(SKU[[#This Row],[Kit Code]], Rate[], 3, FALSE)*SKU[[#This Row],[Kit Qty]]) -> 0 | J15: 4002276 | K15: =IF(SKU[[#This Row],[Commission Code]]="", 0, VLOOKUP(SKU[[#This Row],[Commission Code]], Rate[], 3, FALSE)*SKU[[#This Row],[Ship Qty]]) -> 0 | L15: =SKU[[#This Row],[Ship Cost]]+SKU[[#This Row],[Kit Cost]]+SKU[[#This Row],[Comission Cost]] -> 0 | M15: =IF(OR(ISNA(SKU[[#This Row],[Ship Cost]]), ISNA(SKU[[#This Row],[Kit Cost]]), ISNA(SKU[[#This Row],[Comission Cost]])), "Error Accessing SAP Rate", "")
A16: xy-gw-g2x-au | B16: XY Gateway Extend (Gen 2) 106-1002 AU | C16: 4002239 | D16: =SUMIF(Ship_SKU[SKU], SKU[[#This Row],[SKU]], Ship_SKU[Qty]) -> 4 | E16: =IF(SKU[[#This Row],[Ship Code]]="", 0, VLOOKUP(SKU[[#This Row],[Ship Code]], Rate[], 3, FALSE)*SKU[[#This Row],[Ship Qty]]) -> 9.92 | F16: 4002240 | G16: 1 | H16: =SKU[[#This Row],[Ship Qty]]*SKU[[#This Row],[Kit Items]] -> 4 | I16: =IF(SKU[[#This Row],[Kit Code]]="", 0, VLOOKUP(SKU[[#This Row],[Kit Code]], Rate[], 3, FALSE)*SKU[[#This Row],[Kit Qty]]) -> 7.56 | K16: =IF(SKU[[#This Row],[Commission Code]]="", 0, VLOOKUP(SKU[[#This Row],[Commission Code]], Rate[], 3, FALSE)*SKU[[#This Row],[Ship Qty]]) -> 0 | L16: =SKU[[#This Row],[Ship Cost]]+SKU[[#This Row],[Kit Cost]]+SKU[[#This Row],[Comission Cost]] -> 17.48 | M16: =IF(OR(ISNA(SKU[[#This Row],[Ship Cost]]), ISNA(SKU[[#This Row],[Kit Cost]]), ISNA(SKU[[#This Row],[Comission Cost]])), "Error Accessing SAP Rate", "")
A17: xy-gw-g2x-br | B17: XY Gateway Extend (Gen 2) 106-1002 BR | C17: 4002239 | D17: =SUMIF(Ship_SKU[SKU], SKU[[#This Row],[SKU]], Ship_SKU[Qty]) -> 0 | E17: =IF(SKU[[#This Row],[Ship Code]]="", 0, VLOOKUP(SKU[[#This Row],[Ship Code]], Rate[], 3, FALSE)*SKU[[#This Row],[Ship Qty]]) -> 0 | F17: 4002240 | G17: 1 | H17: =SKU[[#This Row],[Ship Qty]]*SKU[[#This Row],[Kit Items]] -> 0 | I17: =IF(SKU[[#This Row],[Kit Code]]="", 0, VLOOKUP(SKU[[#This Row],[Kit Code]], Rate[], 3, FALSE)*SKU[[#This Row],[Kit Qty]]) -> 0 | K17: =IF(SKU[[#This Row],[Commission Code]]="", 0, VLOOKUP(SKU[[#This Row],[Commission Code]], Rate[], 3, FALSE)*SKU[[#This Row],[Ship Qty]]) -> 0 | L17: =SKU[[#This Row],[Ship Cost]]+SKU[[#This Row],[Kit Cost]]+SKU[[#This Row],[Comission Cost]] -> 0 | M17: =IF(OR(ISNA(SKU[[#This Row],[Ship Cost]]), ISNA(SKU[[#This Row],[Kit Cost]]), ISNA(SKU[[#This Row],[Comission Cost]])), "Error Accessing SAP Rate", "")
A18: xy-gw-g2x-eu | B18: XY Gateway Extend (Gen 2) 106-1002 EU | C18: 4002239 | D18: =SUMIF(Ship_SKU[SKU], SKU[[#This Row],[SKU]], Ship_SKU[Qty]) -> 0 | E18: =IF(SKU[[#This Row],[Ship Code]]="", 0, VLOOKUP(SKU[[#This Row],[Ship Code]], Rate[], 3, FALSE)*SKU[[#This Row],[Ship Qty]]) -> 0 | F18: 4002240 | G18: 1 | H18: =SKU[[#This Row],[Ship Qty]]*SKU[[#This Row],[Kit Items]] -> 0 | I18: =IF(SKU[[#This Row],[Kit Code]]="", 0, VLOOKUP(SKU[[#This Row],[Kit Code]], Rate[], 3, FALSE)*SKU[[#This Row],[Kit Qty]]) -> 0 | K18: =IF(SKU[[#This Row],[Commission Code]]="", 0, VLOOKUP(SKU[[#This Row],[Commission Code]], Rate[], 3, FALSE)*SKU[[#This Row],[Ship Qty]]) -> 0 | L18: =SKU[[#This Row],[Ship Cost]]+SKU[[#This Row],[Kit Cost]]+SKU[[#This Row],[Comission Cost]] -> 0 | M18: =IF(OR(ISNA(SKU[[#This Row],[Ship Cost]]), ISNA(SKU[[#This Row],[Kit Cost]]), ISNA(SKU[[#This Row],[Comission Cost]])), "Error Accessing SAP Rate", "")
A19: xy-gw-g2x-gb | B19: XY Gateway Extend (Gen 2) 106-1002 UK | C19: 4002239 | D19: =SUMIF(Ship_SKU[SKU], SKU[[#This Row],[SKU]], Ship_SKU[Qty]) -> 0 | E19: =IF(SKU[[#This Row],[Ship Code]]="", 0, VLOOKUP(SKU[[#This Row],[Ship Code]], Rate[], 3, FALSE)*SKU[[#This Row],[Ship Qty]]) -> 0 | F19: 4002240 | G19: 1 | H19: =SKU[[#This Row],[Ship Qty]]*SKU[[#This Row],[Kit Items]] -> 0 | I19: =IF(SKU[[#This Row],[Kit Code]]="", 0, VLOOKUP(SKU[[#This Row],[Kit Code]], Rate[], 3, FALSE)*SKU[[#This Row],[Kit Qty]]) -> 0 | K19: =IF(SKU[[#This Row],[Commission Code]]="", 0, VLOOKUP(SKU[[#This Row],[Commission Code]], Rate[], 3, FALSE)*SKU[[#This Row],[Ship Qty]]) -> 0 | L19: =SKU[[#This Row],[Ship Cost]]+SKU[[#This Row],[Kit Cost]]+SKU[[#This Row],[Comission Cost]] -> 0 | M19: =IF(OR(ISNA(SKU[[#This Row],[Ship Cost]]), ISNA(SKU[[#This Row],[Kit Cost]]), ISNA(SKU[[#This Row],[Comission Cost]])), "Error Accessing SAP Rate", "")
A20: xy-gw-g2x-in | B20: XY Gateway Extend (Gen 2) 106-1002 IN | C20: 4002239 | D20: =SUMIF(Ship_SKU[SKU], SKU[[#This Row],[SKU]], Ship_SKU[Qty]) -> 0 | E20: =IF(SKU[[#This Row],[Ship Code]]="", 0, VLOOKUP(SKU[[#This Row],[Ship Code]], Rate[], 3, FALSE)*SKU[[#This Row],[Ship Qty]]) -> 0 | F20: 4002240 | G20: 1 | H20: =SKU[[#This Row],[Ship Qty]]*SKU[[#This Row],[Kit Items]] -> 0 | I20: =IF(SKU[[#This Row],[Kit Code]]="", 0, VLOOKUP(SKU[[#This Row],[Kit Code]], Rate[], 3, FALSE)*SKU[[#This Row],[Kit Qty]]) -> 0 | K20: =IF(SKU[[#This Row],[Commission Code]]="", 0, VLOOKUP(SKU[[#This Row],[Commission Code]], Rate[], 3, FALSE)*SKU[[#This Row],[Ship Qty]]) -> 0 | L20: =SKU[[#This Row],[Ship Cost]]+SKU[[#This Row],[Kit Cost]]+SKU[[#This Row],[Comission Cost]] -> 0 | M20: =IF(OR(ISNA(SKU[[#This Row],[Ship Cost]]), ISNA(SKU[[#This Row],[Kit Cost]]), ISNA(SKU[[#This Row],[Comission Cost]])), "Error Accessing SAP Rate", "")
A21: xy-gw-g2x-us | B21: XY Gateway Extend (Gen 2) 106-1002 US | C21: 4002239 | D21: =SUMIF(Ship_SKU[SKU], SKU[[#This Row],[SKU]], Ship_SKU[Qty]) -> 0 | E21: =IF(SKU[[#This Row],[Ship Code]]="", 0, VLOOKUP(SKU[[#This Row],[Ship Code]], Rate[], 3, FALSE)*SKU[[#This Row],[Ship Qty]]) -> 0 | F21: 4002240 | G21: 1 | H21: =SKU[[#This Row],[Ship Qty]]*SKU[[#This Row],[Kit Items]] -> 0 | I21: =IF(SKU[[#This Row],[Kit Code]]="", 0, VLOOKUP(SKU[[#This Row],[Kit Code]], Rate[], 3, FALSE)*SKU[[#This Row],[Kit Qty]]) -> 0 | K21: =IF(SKU[[#This Row],[Commission Code]]="", 0, VLOOKUP(SKU[[#This Row],[Commission Code]], Rate[], 3, FALSE)*SKU[[#This Row],[Ship Qty]]) -> 0 | L21: =SKU[[#This Row],[Ship Cost]]+SKU[[#This Row],[Kit Cost]]+SKU[[#This Row],[Comission Cost]] -> 0 | M21: =IF(OR(ISNA(SKU[[#This Row],[Ship Cost]]), ISNA(SKU[[#This Row],[Kit Cost]]), ISNA(SKU[[#This Row],[Comission Cost]])), "Error Accessing SAP Rate", "")
A22: xy-hub-3p-ps-868 | B22: XY Presence Hub (MTCAP3-EN-A23UEA-LWM) 868 Mhz | C22: 4002239 | D22: =SUMIF(Ship_SKU[SKU], SKU[[#This Row],[SKU]], Ship_SKU[Qty]) -> 0 | E22: =IF(SKU[[#This Row],[Ship Code]]="", 0, VLOOKUP(SKU[[#This Row],[Ship Code]], Rate[], 3, FALSE)*SKU[[#This Row],[Ship Qty]]) -> 0 | H22: =SKU[[#This Row],[Ship Qty]]*SKU[[#This Row],[Kit Items]] -> 0 | I22: =IF(SKU[[#This Row],[Kit Code]]="", 0, VLOOKUP(SKU[[#This Row],[Kit Code]], Rate[], 3, FALSE)*SKU[[#This Row],[Kit Qty]]) -> 0 | J22: 4002242 | K22: =IF(SKU[[#This Row],[Commission Code]]="", 0, VLOOKUP(SKU[[#This Row],[Commission Code]], Rate[], 3, FALSE)*SKU[[#This Row],[Ship Qty]]) -> 0 | L22: =SKU[[#This Row],[Ship Cost]]+SKU[[#This Row],[Kit Cost]]+SKU[[#This Row],[Comission Cost]] -> 0 | M22: =IF(OR(ISNA(SKU[[#This Row],[Ship Cost]]), ISNA(SKU[[#This Row],[Kit Cost]]), ISNA(SKU[[#This Row],[Comission Cost]])), "Error Accessing SAP Rate", "")
A23: xy-hub-3p-ps-868-eu | B23: XY Presence Hub 868Mhz EU | C23: 4002239 | D23: =SUMIF(Ship_SKU[SKU], SKU[[#This Row],[SKU]], Ship_SKU[Qty]) -> 0 | E23: =IF(SKU[[#This Row],[Ship Code]]="", 0, VLOOKUP(SKU[[#This Row],[Ship Code]], Rate[], 3, FALSE)*SKU[[#This Row],[Ship Qty]]) -> 0 | H23: =SKU[[#This Row],[Ship Qty]]*SKU[[#This Row],[Kit Items]] -> 0 | I23: =IF(SKU[[#This Row],[Kit Code]]="", 0, VLOOKUP(SKU[[#This Row],[Kit Code]], Rate[], 3, FALSE)*SKU[[#This Row],[Kit Qty]]) -> 0 | J23: 4002242 | K23: =IF(SKU[[#This Row],[Commission Code]]="", 0, VLOOKUP(SKU[[#This Row],[Commission Code]], Rate[], 3, FALSE)*SKU[[#This Row],[Ship Qty]]) -> 0 | L23: =SKU[[#This Row],[Ship Cost]]+SKU[[#This Row],[Kit Cost]]+SKU[[#This Row],[Comission Cost]] -> 0 | M23: =IF(OR(ISNA(SKU[[#This Row],[Ship Cost]]), ISNA(SKU[[#This Row],[Kit Cost]]), ISNA(SKU[[#This Row],[Comission Cost]])), "Error Accessing SAP Rate", "")
A24: xy-hub-3p-ps-868-gb | B24: XY Presence Hub 868Mhz UK | C24: 4002239 | D24: =SUMIF(Ship_SKU[SKU], SKU[[#This Row],[SKU]], Ship_SKU[Qty]) -> 0 | E24: =IF(SKU[[#This Row],[Ship Code]]="", 0, VLOOKUP(SKU[[#This Row],[Ship Code]], Rate[], 3, FALSE)*SKU[[#This Row],[Ship Qty]]) -> 0 | H24: =SKU[[#This Row],[Ship Qty]]*SKU[[#This Row],[Kit Items]] -> 0 | I24: =IF(SKU[[#This Row],[Kit Code]]="", 0, VLOOKUP(SKU[[#This Row],[Kit Code]], Rate[], 3, FALSE)*SKU[[#This Row],[Kit Qty]]) -> 0 | J24: 4002242 | K24: =IF(SKU[[#This Row],[Commission Code]]="", 0, VLOOKUP(SKU[[#This Row],[Commission Code]], Rate[], 3, FALSE)*SKU[[#This Row],[Ship Qty]]) -> 0 | L24: =SKU[[#This Row],[Ship Cost]]+SKU[[#This Row],[Kit Cost]]+SKU[[#This Row],[Comission Cost]] -> 0 | M24: =IF(OR(ISNA(SKU[[#This Row],[Ship Cost]]), ISNA(SKU[[#This Row],[Kit Cost]]), ISNA(SKU[[#This Row],[Comission Cost]])), "Error Accessing SAP Rate", "")
A25: xy-hub-3p-ps-868-in | B25: XY Presence Hub 868Mhz IN | C25: 4002239 | D25: =SUMIF(Ship_SKU[SKU], SKU[[#This Row],[SKU]], Ship_SKU[Qty]) -> 0 | E25: =IF(SKU[[#This Row],[Ship Code]]="", 0, VLOOKUP(SKU[[#This Row],[Ship Code]], Rate[], 3, FALSE)*SKU[[#This Row],[Ship Qty]]) -> 0 | H25: =SKU[[#This Row],[Ship Qty]]*SKU[[#This Row],[Kit Items]] -> 0 | I25: =IF(SKU[[#This Row],[Kit Code]]="", 0, VLOOKUP(SKU[[#This Row],[Kit Code]], Rate[], 3, FALSE)*SKU[[#This Row],[Kit Qty]]) -> 0 | J25: 4002242 | K25: =IF(SKU[[#This Row],[Commission Code]]="", 0, VLOOKUP(SKU[[#This Row],[Commission Code]], Rate[], 3, FALSE)*SKU[[#This Row],[Ship Qty]]) -> 0 | L25: =SKU[[#This Row],[Ship Cost]]+SKU[[#This Row],[Kit Cost]]+SKU[[#This Row],[Comission Cost]] -> 0 | M25: =IF(OR(ISNA(SKU[[#This Row],[Ship Cost]]), ISNA(SKU[[#This Row],[Kit Cost]]), ISNA(SKU[[#This Row],[Comission Cost]])), "Error Accessing SAP Rate", "")
A26: xy-hub-3p-ps-915 | B26: XY Presence Hub (MTCAP3-EN-A23UEA-LWM) 915Mhz | C26: 4002239 | D26: =SUMIF(Ship_SKU[SKU], SKU[[#This Row],[SKU]], Ship_SKU[Qty]) -> 2 | E26: =IF(SKU[[#This Row],[Ship Code]]="", 0, VLOOKUP(SKU[[#This Row],[Ship Code]], Rate[], 3, FALSE)*SKU[[#This Row],[Ship Qty]]) -> 4.96 | H26: =SKU[[#This Row],[Ship Qty]]*SKU[[#This Row],[Kit Items]] -> 0 | I26: =IF(SKU[[#This Row],[Kit Code]]="", 0, VLOOKUP(SKU[[#This Row],[Kit Code]], Rate[], 3, FALSE)*SKU[[#This Row],[Kit Qty]]) -> 0 | J26: 4002242 | K26: =IF(SKU[[#This Row],[Commission Code]]="", 0, VLOOKUP(SKU[[#This Row],[Commission Code]], Rate[], 3, FALSE)*SKU[[#This Row],[Ship Qty]]) -> 21.98 | L26: =SKU[[#This Row],[Ship Cost]]+SKU[[#This Row],[Kit Cost]]+SKU[[#This Row],[Comission Cost]] -> 26.94 | M26: =IF(OR(ISNA(SKU[[#This Row],[Ship Cost]]), ISNA(SKU[[#This Row],[Kit Cost]]), ISNA(SKU[[#This Row],[Comission Cost]])), "Error Accessing SAP Rate", "")
A27: xy-hub-3p-ps-915-au | B27: XY Presence Hub 915Mhz AU | C27: 4002239 | D27: =SUMIF(Ship_SKU[SKU], SKU[[#This Row],[SKU]], Ship_SKU[Qty]) -> 0 | E27: =IF(SKU[[#This Row],[Ship Code]]="", 0, VLOOKUP(SKU[[#This Row],[Ship Code]], Rate[], 3, FALSE)*SKU[[#This Row],[Ship Qty]]) -> 0 | H27: =SKU[[#This Row],[Ship Qty]]*SKU[[#This Row],[Kit Items]] -> 0 | I27: =IF(SKU[[#This Row],[Kit Code]]="", 0, VLOOKUP(SKU[[#This Row],[Kit Code]], Rate[], 3, FALSE)*SKU[[#This Row],[Kit Qty]]) -> 0 | J27: 4002242 | K27: =IF(SKU[[#This Row],[Commission Code]]="", 0, VLOOKUP(SKU[[#This Row],[Commission Code]], Rate[], 3, FALSE)*SKU[[#This Row],[Ship Qty]]) -> 0 | L27: =SKU[[#This Row],[Ship Cost]]+SKU[[#This Row],[Kit Cost]]+SKU[[#This Row],[Comission Cost]] -> 0 | M27: =IF(OR(ISNA(SKU[[#This Row],[Ship Cost]]), ISNA(SKU[[#This Row],[Kit Cost]]), ISNA(SKU[[#This Row],[Comission Cost]])), "Error Accessing SAP Rate", "")
A28: xy-hub-3p-ps-915-us | B28: XY Presence Hub 915Mhz US | C28: 4002239 | D28: =SUMIF(Ship_SKU[SKU], SKU[[#This Row],[SKU]], Ship_SKU[Qty]) -> 0 | E28: =IF(SKU[[#This Row],[Ship Code]]="", 0, VLOOKUP(SKU[[#This Row],[Ship Code]], Rate[], 3, FALSE)*SKU[[#This Row],[Ship Qty]]) -> 0 | H28: =SKU[[#This Row],[Ship Qty]]*SKU[[#This Row],[Kit Items]] -> 0 | I28: =IF(SKU[[#This Row],[Kit Code]]="", 0, VLOOKUP(SKU[[#This Row],[Kit Code]], Rate[], 3, FALSE)*SKU[[#This Row],[Kit Qty]]) -> 0 | J28: 4002242 | K28: =IF(SKU[[#This Row],[Commission Code]]="", 0, VLOOKUP(SKU[[#This Row],[Commission Code]], Rate[], 3, FALSE)*SKU[[#This Row],[Ship Qty]]) -> 0 | L28: =SKU[[#This Row],[Ship Cost]]+SKU[[#This Row],[Kit Cost]]+SKU[[#This Row],[Comission Cost]] -> 0 | M28: =IF(OR(ISNA(SKU[[#This Row],[Ship Cost]]), ISNA(SKU[[#This Row],[Kit Cost]]), ISNA(SKU[[#This Row],[Comission Cost]])), "Error Accessing SAP Rate", "")
A29: xy-hub-3p-ps-ms-868 | B29: XY Presence Hub (ND56 MS) 868 Mhz | C29: 4002239 | D29: =SUMIF(Ship_SKU[SKU], SKU[[#This Row],[SKU]], Ship_SKU[Qty]) -> 0 | E29: =IF(SKU[[#This Row],[Ship Code]]="", 0, VLOOKUP(SKU[[#This Row],[Ship Code]], Rate[], 3, FALSE)*SKU[[#This Row],[Ship Qty]]) -> 0 | H29: =SKU[[#This Row],[Ship Qty]]*SKU[[#This Row],[Kit Items]] -> 0 | I29: =IF(SKU[[#This Row],[Kit Code]]="", 0, VLOOKUP(SKU[[#This Row],[Kit Code]], Rate[], 3, FALSE)*SKU[[#This Row],[Kit Qty]]) -> 0 | J29: 4002242 | K29: =IF(SKU[[#This Row],[Commission Code]]="", 0, VLOOKUP(SKU[[#This Row],[Commission Code]], Rate[], 3, FALSE)*SKU[[#This Row],[Ship Qty]]) -> 0 | L29: =SKU[[#This Row],[Ship Cost]]+SKU[[#This Row],[Kit Cost]]+SKU[[#This Row],[Comission Cost]] -> 0 | M29: =IF(OR(ISNA(SKU[[#This Row],[Ship Cost]]), ISNA(SKU[[#This Row],[Kit Cost]]), ISNA(SKU[[#This Row],[Comission Cost]])), "Error Accessing SAP Rate", "")
A30: xy-hub-3p-ps-ms-868-eu | B30: XY Presence Hub MS 868Mhz EU | C30: 4002239 | D30: =SUMIF(Ship_SKU[SKU], SKU[[#This Row],[SKU]], Ship_SKU[Qty]) -> 0 | E30: =IF(SKU[[#This Row],[Ship Code]]="", 0, VLOOKUP(SKU[[#This Row],[Ship Code]], Rate[], 3, FALSE)*SKU[[#This Row],[Ship Qty]]) -> 0 | H30: =SKU[[#This Row],[Ship Qty]]*SKU[[#This Row],[Kit Items]] -> 0 | I30: =IF(SKU[[#This Row],[Kit Code]]="", 0, VLOOKUP(SKU[[#This Row],[Kit Code]], Rate[], 3, FALSE)*SKU[[#This Row],[Kit Qty]]) -> 0 | J30: 4002242 | K30: =IF(SKU[[#This Row],[Commission Code]]="", 0, VLOOKUP(SKU[[#This Row],[Commission Code]], Rate[], 3, FALSE)*SKU[[#This Row],[Ship Qty]]) -> 0 | L30: =SKU[[#This Row],[Ship Cost]]+SKU[[#This Row],[Kit Cost]]+SKU[[#This Row],[Comission Cost]] -> 0 | M30: =IF(OR(ISNA(SKU[[#This Row],[Ship Cost]]), ISNA(SKU[[#This Row],[Kit Cost]]), ISNA(SKU[[#This Row],[Comission Cost]])), "Error Accessing SAP Rate", "")
A31: xy-hub-3p-ps-ms-868-gb | B31: XY Presence Hub MS 868Mhz UK | C31: 4002239 | D31: =SUMIF(Ship_SKU[SKU], SKU[[#This Row],[SKU]], Ship_SKU[Qty]) -> 0 | E31: =IF(SKU[[#This Row],[Ship Code]]="", 0, VLOOKUP(SKU[[#This Row],[Ship Code]], Rate[], 3, FALSE)*SKU[[#This Row],[Ship Qty]]) -> 0 | H31: =SKU[[#This Row],[Ship Qty]]*SKU[[#This Row],[Kit Items]] -> 0 | I31: =IF(SKU[[#This Row],[Kit Code]]="", 0, VLOOKUP(SKU[[#This Row],[Kit Code]], Rate[], 3, FALSE)*SKU[[#This Row],[Kit Qty]]) -> 0 | J31: 4002242 | K31: =IF(SKU[[#This Row],[Commission Code]]="", 0, VLOOKUP(SKU[[#This Row],[Commission Code]], Rate[], 3, FALSE)*SKU[[#This Row],[Ship Qty]]) -> 0 | L31: =SKU[[#This Row],[Ship Cost]]+SKU[[#This Row],[Kit Cost]]+SKU[[#This Row],[Comission Cost]] -> 0 | M31: =IF(OR(ISNA(SKU[[#This Row],[Ship Cost]]), ISNA(SKU[[#This Row],[Kit Cost]]), ISNA(SKU[[#This Row],[Comission Cost]])), "Error Accessing SAP Rate", "")
A32: xy-hub-3p-ps-ms-868-in | B32: XY Presence Hub MS 868Mhz IN | C32: 4002239 | D32: =SUMIF(Ship_SKU[SKU], SKU[[#This Row],[SKU]], Ship_SKU[Qty]) -> 0 | E32: =IF(SKU[[#This Row],[Ship Code]]="", 0, VLOOKUP(SKU[[#This Row],[Ship Code]], Rate[], 3, FALSE)*SKU[[#This Row],[Ship Qty]]) -> 0 | H32: =SKU[[#This Row],[Ship Qty]]*SKU[[#This Row],[Kit Items]] -> 0 | I32: =IF(SKU[[#This Row],[Kit Code]]="", 0, VLOOKUP(SKU[[#This Row],[Kit Code]], Rate[], 3, FALSE)*SKU[[#This Row],[Kit Qty]]) -> 0 | J32: 4002242 | K32: =IF(SKU[[#This Row],[Commission Code]]="", 0, VLOOKUP(SKU[[#This Row],[Commission Code]], Rate[], 3, FALSE)*SKU[[#This Row],[Ship Qty]]) -> 0 | L32: =SKU[[#This Row],[Ship Cost]]+SKU[[#This Row],[Kit Cost]]+SKU[[#This Row],[Comission Cost]] -> 0 | M32: =IF(OR(ISNA(SKU[[#This Row],[Ship Cost]]), ISNA(SKU[[#This Row],[Kit Cost]]), ISNA(SKU[[#This Row],[Comission Cost]])), "Error Accessing SAP Rate", "")
A33: xy-hub-3p-ps-ms-915 | B33: XY Presence Hub (ND56 MS) 915Mhz | C33: 4002239 | D33: =SUMIF(Ship_SKU[SKU], SKU[[#This Row],[SKU]], Ship_SKU[Qty]) -> 0 | E33: =IF(SKU[[#This Row],[Ship Code]]="", 0, VLOOKUP(SKU[[#This Row],[Ship Code]], Rate[], 3, FALSE)*SKU[[#This Row],[Ship Qty]]) -> 0 | H33: =SKU[[#This Row],[Ship Qty]]*SKU[[#This Row],[Kit Items]] -> 0 | I33: =IF(SKU[[#This Row],[Kit Code]]="", 0, VLOOKUP(SKU[[#This Row],[Kit Code]], Rate[], 3, FALSE)*SKU[[#This Row],[Kit Qty]]) -> 0 | J33: 4002242 | K33: =IF(SKU[[#This Row],[Commission Code]]="", 0, VLOOKUP(SKU[[#This Row],[Commission Code]], Rate[], 3, FALSE)*SKU[[#This Row],[Ship Qty]]) -> 0 | L33: =SKU[[#This Row],[Ship Cost]]+SKU[[#This Row],[Kit Cost]]+SKU[[#This Row],[Comission Cost]] -> 0 | M33: =IF(OR(ISNA(SKU[[#This Row],[Ship Cost]]), ISNA(SKU[[#This Row],[Kit Cost]]), ISNA(SKU[[#This Row],[Comission Cost]])), "Error Accessing SAP Rate", "")
... A35: xy-hub-3p-ps-ms-915-us | B35: XY Presence Hub MS 915Mhz US | C35: 4002239 | D35: =SUMIF(Ship_SKU[SKU], SKU[[#This Row],[SKU]], Ship_SKU[Qty]) -> 0 | E35: =IF(SKU[[#This Row],[Ship Code]]="", 0, VLOOKUP(SKU[[#This Row],[Ship Code]], Rate[], 3, FALSE)*SKU[[#This Row],[Ship Qty]]) -> 0 | H35: =SKU[[#This Row],[Ship Qty]]*SKU[[#This Row],[Kit Items]] -> 0 | I35: =IF(SKU[[#This Row],[Kit Code]]="", 0, VLOOKUP(SKU[[#This Row],[Kit Code]], Rate[], 3, FALSE)*SKU[[#This Row],[Kit Qty]]) -> 0 | J35: 4002242 | K35: =IF(SKU[[#This Row],[Commission Code]]="", 0, VLOOKUP(SKU[[#This Row],[Commission Code]], Rate[], 3, FALSE)*SKU[[#This Row],[Ship Qty]]) -> 0 | L35: =SKU[[#This Row],[Ship Cost]]+SKU[[#This Row],[Kit Cost]]+SKU[[#This Row],[Comission Cost]] -> 0 | M35: =IF(OR(ISNA(SKU[[#This Row],[Ship Cost]]), ISNA(SKU[[#This Row],[Kit Cost]]), ISNA(SKU[[#This Row],[Comission Cost]])), "Error Accessing SAP Rate", "")
A36: xy-hub-pr-au | B36: XY Primary Hub 104-1001 AU | C36: 4002239 | D36: =SUMIF(Ship_SKU[SKU], SKU[[#This Row],[SKU]], Ship_SKU[Qty]) -> 0 | E36: =IF(SKU[[#This Row],[Ship Code]]="", 0, VLOOKUP(SKU[[#This Row],[Ship Code]], Rate[], 3, FALSE)*SKU[[#This Row],[Ship Qty]]) -> 0 | F36: 4002240 | G36: 3 | H36: =SKU[[#This Row],[Ship Qty]]*SKU[[#This Row],[Kit Items]] -> 0 | I36: =IF(SKU[[#This Row],[Kit Code]]="", 0, VLOOKUP(SKU[[#This Row],[Kit Code]], Rate[], 3, FALSE)*SKU[[#This Row],[Kit Qty]]) -> 0 | K36: =IF(SKU[[#This Row],[Commission Code]]="", 0, VLOOKUP(SKU[[#This Row],[Commission Code]], Rate[], 3, FALSE)*SKU[[#This Row],[Ship Qty]]) -> 0 | L36: =SKU[[#This Row],[Ship Cost]]+SKU[[#This Row],[Kit Cost]]+SKU[[#This Row],[Comission Cost]] -> 0 | M36: =IF(OR(ISNA(SKU[[#This Row],[Ship Cost]]), ISNA(SKU[[#This Row],[Kit Cost]]), ISNA(SKU[[#This Row],[Comission Cost]])), "Error Accessing SAP Rate", "")
A37: xy-hub-pr-au-r | B37: XY Primary Hub 104-1001 (Refurbished) (AU) | C37: 4002239 | D37: =SUMIF(Ship_SKU[SKU], SKU[[#This Row],[SKU]], Ship_SKU[Qty]) -> 0 | E37: =IF(SKU[[#This Row],[Ship Code]]="", 0, VLOOKUP(SKU[[#This Row],[Ship Code]], Rate[], 3, FALSE)*SKU[[#This Row],[Ship Qty]]) -> 0 | H37: =SKU[[#This Row],[Ship Qty]]*SKU[[#This Row],[Kit Items]] -> 0 | I37: =IF(SKU[[#This Row],[Kit Code]]="", 0, VLOOKUP(SKU[[#This Row],[Kit Code]], Rate[], 3, FALSE)*SKU[[#This Row],[Kit Qty]]) -> 0 | K37: =IF(SKU[[#This Row],[Commission Code]]="", 0, VLOOKUP(SKU[[#This Row],[Commission Code]], Rate[], 3, FALSE)*SKU[[#This Row],[Ship Qty]]) -> 0 | L37: =SKU[[#This Row],[Ship Cost]]+SKU[[#This Row],[Kit Cost]]+SKU[[#This Row],[Comission Cost]] -> 0 | M37: =IF(OR(ISNA(SKU[[#This Row],[Ship Cost]]), ISNA(SKU[[#This Row],[Kit Cost]]), ISNA(SKU[[#This Row],[Comission Cost]])), "Error Accessing SAP Rate", "")
A38: xy-hub-pr-ca | B38: XY Primary Hub 104-1001 CA | C38: 4002239 | D38: =SUMIF(Ship_SKU[SKU], SKU[[#This Row],[SKU]], Ship_SKU[Qty]) -> 0 | E38: =IF(SKU[[#This Row],[Ship Code]]="", 0, VLOOKUP(SKU[[#This Row],[Ship Code]], Rate[], 3, FALSE)*SKU[[#This Row],[Ship Qty]]) -> 0 | F38: 4002240 | G38: 3 | H38: =SKU[[#This Row],[Ship Qty]]*SKU[[#This Row],[Kit Items]] -> 0 | I38: =IF(SKU[[#This Row],[Kit Code]]="", 0, VLOOKUP(SKU[[#This Row],[Kit Code]], Rate[], 3, FALSE)*SKU[[#This Row],[Kit Qty]]) -> 0 | K38: =IF(SKU[[#This Row],[Commission Code]]="", 0, VLOOKUP(SKU[[#This Row],[Commission Code]], Rate[], 3, FALSE)*SKU[[#This Row],[Ship Qty]]) -> 0 | L38: =SKU[[#This Row],[Ship Cost]]+SKU[[#This Row],[Kit Cost]]+SKU[[#This Row],[Comission Cost]] -> 0 | M38: =IF(OR(ISNA(SKU[[#This Row],[Ship Cost]]), ISNA(SKU[[#This Row],[Kit Cost]]), ISNA(SKU[[#This Row],[Comission Cost]])), "Error Accessing SAP Rate", "")
A39: xy-hub-pr-eu | B39: XY Primary Hub 104-1001 EU | C39: 4002239 | D39: =SUMIF(Ship_SKU[SKU], SKU[[#This Row],[SKU]], Ship_SKU[Qty]) -> 0 | E39: =IF(SKU[[#This Row],[Ship Code]]="", 0, VLOOKUP(SKU[[#This Row],[Ship Code]], Rate[], 3, FALSE)*SKU[[#This Row],[Ship Qty]]) -> 0 | F39: 4002240 | G39: 3 | H39: =SKU[[#This Row],[Ship Qty]]*SKU[[#This Row],[Kit Items]] -> 0 | I39: =IF(SKU[[#This Row],[Kit Code]]="", 0, VLOOKUP(SKU[[#This Row],[Kit Code]], Rate[], 3, FALSE)*SKU[[#This Row],[Kit Qty]]) -> 0 | K39: =IF(SKU[[#This Row],[Commission Code]]="", 0, VLOOKUP(SKU[[#This Row],[Commission Code]], Rate[], 3, FALSE)*SKU[[#This Row],[Ship Qty]]) -> 0 | L39: =SKU[[#This Row],[Ship Cost]]+SKU[[#This Row],[Kit Cost]]+SKU[[#This Row],[Comission Cost]] -> 0 | M39: =IF(OR(ISNA(SKU[[#This Row],[Ship Cost]]), ISNA(SKU[[#This Row],[Kit Cost]]), ISNA(SKU[[#This Row],[Comission Cost]])), "Error Accessing SAP Rate", "")
A40: xy-hub-pr-gb | B40: XY Primary Hub 104-1001 GB | C40: 4002239 | D40: =SUMIF(Ship_SKU[SKU], SKU[[#This Row],[SKU]], Ship_SKU[Qty]) -> 0 | E40: =IF(SKU[[#This Row],[Ship Code]]="", 0, VLOOKUP(SKU[[#This Row],[Ship Code]], Rate[], 3, FALSE)*SKU[[#This Row],[Ship Qty]]) -> 0 | F40: 4002240 | G40: 3 | H40: =SKU[[#This Row],[Ship Qty]]*SKU[[#This Row],[Kit Items]] -> 0 | I40: =IF(SKU[[#This Row],[Kit Code]]="", 0, VLOOKUP(SKU[[#This Row],[Kit Code]], Rate[], 3, FALSE)*SKU[[#This Row],[Kit Qty]]) -> 0 | K40: =IF(SKU[[#This Row],[Commission Code]]="", 0, VLOOKUP(SKU[[#This Row],[Commission Code]], Rate[], 3, FALSE)*SKU[[#This Row],[Ship Qty]]) -> 0 | L40: =SKU[[#This Row],[Ship Cost]]+SKU[[#This Row],[Kit Cost]]+SKU[[#This Row],[Comission Cost]] -> 0 | M40: =IF(OR(ISNA(SKU[[#This Row],[Ship Cost]]), ISNA(SKU[[#This Row],[Kit Cost]]), ISNA(SKU[[#This Row],[Comission Cost]])), "Error Accessing SAP Rate", "")
A41: xy-hub-pr-hk | B41: XY Primary Hub 104-1001 HK | C41: 4002239 | D41: =SUMIF(Ship_SKU[SKU], SKU[[#This Row],[SKU]], Ship_SKU[Qty]) -> 0 | E41: =IF(SKU[[#This Row],[Ship Code]]="", 0, VLOOKUP(SKU[[#This Row],[Ship Code]], Rate[], 3, FALSE)*SKU[[#This Row],[Ship Qty]]) -> 0 | F41: 4002240 | G41: 3 | H41: =SKU[[#This Row],[Ship Qty]]*SKU[[#This Row],[Kit Items]] -> 0 | I41: =IF(SKU[[#This Row],[Kit Code]]="", 0, VLOOKUP(SKU[[#This Row],[Kit Code]], Rate[], 3, FALSE)*SKU[[#This Row],[Kit Qty]]) -> 0 | K41: =IF(SKU[[#This Row],[Commission Code]]="", 0, VLOOKUP(SKU[[#This Row],[Commission Code]], Rate[], 3, FALSE)*SKU[[#This Row],[Ship Qty]]) -> 0 | L41: =SKU[[#This Row],[Ship Cost]]+SKU[[#This Row],[Kit Cost]]+SKU[[#This Row],[Comission Cost]] -> 0 | M41: =IF(OR(ISNA(SKU[[#This Row],[Ship Cost]]), ISNA(SKU[[#This Row],[Kit Cost]]), ISNA(SKU[[#This Row],[Comission Cost]])), "Error Accessing SAP Rate", "")
...

Sheet Type Summary
A1: REF | B1: Name | C1: Ship Code | D1: Ship Qty | E1: Ship Cost | F1: Box Code | G1: Box Qty | H1: Box Cost | I1: Cost | J1: Error
A2: xy_domestic | B2: Domestic | D2: =SUMIF(Ship_Type[REF], Type[[#This Row],[REF]], Ship_Type[Orders]) -> 0 | E2: =IF(Type[[#This Row],[Ship Code]]="", 0, VLOOKUP(Type[[#This Row],[Ship Code]], Rate[], 3, FALSE)*Type[[#This Row],[Ship Qty]]) -> 0 | F2: 4002238 | G2: =SUMIF(Ship_Type[REF], Type[[#This Row],[REF]], Ship_Type[Boxes]) -> 0 | H2: =IF(Type[[#This Row],[Box Code]]="", 0, VLOOKUP(Type[[#This Row],[Box Code]], Rate[], 3, FALSE)*Type[[#This Row],[Box Qty]]) -> 0 | I2: =SUM(Type[[#This Row],[Ship Cost]], Type[[#This Row],[Box Cost]]) -> 0 | J2: =IF(OR(ISNA(Type[[#This Row],[Ship Cost]]), ISNA(Type[[#This Row],[Box Cost]])), "Error Accessing SAP Rate", "")
A3: xy_international | B3: International | D3: =SUMIF(Ship_Type[REF], Type[[#This Row],[REF]], Ship_Type[Orders]) -> 3 | E3: =IF(Type[[#This Row],[Ship Code]]="", 0, VLOOKUP(Type[[#This Row],[Ship Code]], Rate[], 3, FALSE)*Type[[#This Row],[Ship Qty]]) -> 0 | F3: 4002237 | G3: =SUMIF(Ship_Type[REF], Type[[#This Row],[REF]], Ship_Type[Boxes]) -> 11 | H3: =IF(Type[[#This Row],[Box Code]]="", 0, VLOOKUP(Type[[#This Row],[Box Code]], Rate[], 3, FALSE)*Type[[#This Row],[Box Qty]]) -> 60.39 | I3: =SUM(Type[[#This Row],[Ship Cost]], Type[[#This Row],[Box Cost]]) -> 60.39 | J3: =IF(OR(ISNA(Type[[#This Row],[Ship Cost]]), ISNA(Type[[#This Row],[Box Cost]])), "Error Accessing SAP Rate", "")
A4: xy_pallet | B4: Palletized | D4: =SUMIF(Ship_Type[REF], Type[[#This Row],[REF]], Ship_Type[Orders]) -> 0 | E4: =IF(Type[[#This Row],[Ship Code]]="", 0, VLOOKUP(Type[[#This Row],[Ship Code]], Rate[], 3, FALSE)*Type[[#This Row],[Ship Qty]]) -> 0 | F4: 4002238 | G4: =SUMIF(Ship_Type[REF], Type[[#This Row],[REF]], Ship_Type[Boxes]) -> 0 | H4: =IF(Type[[#This Row],[Box Code]]="", 0, VLOOKUP(Type[[#This Row],[Box Code]], Rate[], 3, FALSE)*Type[[#This Row],[Box Qty]]) -> 0 | I4: =SUM(Type[[#This Row],[Ship Cost]], Type[[#This Row],[Box Cost]]) -> 0 | J4: =IF(OR(ISNA(Type[[#This Row],[Ship Cost]]), ISNA(Type[[#This Row],[Box Cost]])), "Error Accessing SAP Rate", "")
A5: xy_express | B5: Standard | D5: =SUMIF(Ship_Type[REF], Type[[#This Row],[REF]], Ship_Type[Orders]) -> 0 | E5: =IF(Type[[#This Row],[Ship Code]]="", 0, VLOOKUP(Type[[#This Row],[Ship Code]], Rate[], 3, FALSE)*Type[[#This Row],[Ship Qty]]) -> 0 | F5: 4002238 | G5: =SUMIF(Ship_Type[REF], Type[[#This Row],[REF]], Ship_Type[Boxes]) -> 0 | H5: =IF(Type[[#This Row],[Box Code]]="", 0, VLOOKUP(Type[[#This Row],[Box Code]], Rate[], 3, FALSE)*Type[[#This Row],[Box Qty]]) -> 0 | I5: =SUM(Type[[#This Row],[Ship Cost]], Type[[#This Row],[Box Cost]]) -> 0 | J5: =IF(OR(ISNA(Type[[#This Row],[Ship Cost]]), ISNA(Type[[#This Row],[Box Cost]])), "Error Accessing SAP Rate", "")
E7: =SUM(Type[Ship Cost]) -> 0 | H7: =SUM(Type[Box Cost]) -> 60.39 | I7: =SUM(Type[Cost]) -> 60.39

Sheet Summary
A1: SAP Code | B1: Item | C1: Rate | D1: Qty | E1: Total
B2: Kitting
A3: 4002240 | B3: =VLOOKUP(A3, Rate[[SAP Code]:[Qty]], 2, FALSE) -> Kitting - Per part fee | C3: =VLOOKUP($A3, Rate[[SAP Code]:[Qty]], 3, FALSE) -> 1.89 | D3: =VLOOKUP($A3, Rate[[SAP Code]:[Qty]], 9, FALSE) -> 157 | E3: =C3*D3 -> 296.73
B5: Commissioning
A6: 4002242 | B6: =VLOOKUP(A6, Rate[[SAP Code]:[Qty]], 2, FALSE) -> Commissioning - Presence HUB | C6: =VLOOKUP($A6, Rate[[SAP Code]:[Qty]], 3, FALSE) -> 10.99 | D6: =VLOOKUP($A6, Rate[[SAP Code]:[Qty]], 9, FALSE) -> 2 | E6: =C6*D6 -> 21.98
A7: 4002243 | B7: =VLOOKUP(A7, Rate[[SAP Code]:[Qty]], 2, FALSE) -> Commissioning - Presence Sensor | C7: =VLOOKUP($A7, Rate[[SAP Code]:[Qty]], 3, FALSE) -> 2.95 | D7: =VLOOKUP($A7, Rate[[SAP Code]:[Qty]], 9, FALSE) -> 38 | E7: =C7*D7 -> 112.1
A8: 4002276 | B8: =VLOOKUP(A8, Rate[[SAP Code]:[Qty]], 2, FALSE) -> Commissioning - Gateway Primary | C8: =VLOOKUP($A8, Rate[[SAP Code]:[Qty]], 3, FALSE) -> 14.67 | D8: =VLOOKUP($A8, Rate[[SAP Code]:[Qty]], 9, FALSE) -> 0 | E8: =C8*D8 -> 0
A9: 4002277 | B9: =VLOOKUP(A9, Rate[[SAP Code]:[Qty]], 2, FALSE) -> Commissioning – Router AU with Telstra SIM | C9: =VLOOKUP($A9, Rate[[SAP Code]:[Qty]], 3, FALSE) -> 13.89 | D9: =VLOOKUP($A9, Rate[[SAP Code]:[Qty]], 9, FALSE) -> 0 | E9: =C9*D9 -> 0
B11: Drop Ship Services
A12: 4002237 | B12: =VLOOKUP($A12, Rate[[SAP Code]:[Qty]], 2, FALSE) -> Dropship - Per article fee (International) | C12: =VLOOKUP($A12, Rate[[SAP Code]:[Qty]], 3, FALSE) -> 5.49 | D12: =VLOOKUP($A12, Rate[[SAP Code]:[Qty]], 9, FALSE) -> 11 | E12: =C12*D12 -> 60.39
A13: 4002238 | B13: =VLOOKUP(A13, Rate[[SAP Code]:[Qty]], 2, FALSE) -> Dropship - Per article fee (Australia-wide) | C13: =VLOOKUP($A13, Rate[[SAP Code]:[Qty]], 3, FALSE) -> 3.28 | D13: =VLOOKUP($A13, Rate[[SAP Code]:[Qty]], 9, FALSE) -> 0 | E13: =C13*D13 -> 0
A14: 4002239 | B14: =VLOOKUP(A14, Rate[[SAP Code]:[Qty]], 2, FALSE) -> Dropship - Per item fee | C14: =VLOOKUP($A14, Rate[[SAP Code]:[Qty]], 3, FALSE) -> 2.48 | D14: =VLOOKUP($A14, Rate[[SAP Code]:[Qty]], 9, FALSE) -> 189 | E14: =C14*D14 -> 468.72
B16: Return to Sender (RTS Processing)
A17: 4002244 | B17: =VLOOKUP(A17, Rate[[SAP Code]:[Qty]], 2, FALSE) -> RTS - Per Order Fee | C17: =VLOOKUP($A17, Rate[[SAP Code]:[Qty]], 3, FALSE) -> 5.57 | D17: 0 | E17: =C17*D17 -> 0
B19: Other Services
A20: Storage | B20: =VLOOKUP(A20, Rate[[SAP Code]:[Qty]], 2, FALSE) -> Pallet Storage | C20: =VLOOKUP($A20, Rate[[SAP Code]:[Qty]], 3, FALSE) -> 6.2 | E20: =C20*D20 -> 0
A21: Freight | B21: =VLOOKUP(A21, Rate[[SAP Code]:[Qty]], 2, FALSE) -> Sub-Account Freight Costs | C21: =VLOOKUP($A21, Rate[[SAP Code]:[Qty]], 3, FALSE) -> 1 | E21: =C21*D21 -> 0
A22: Adhoc | B22: =VLOOKUP(A22, Rate[[SAP Code]:[Qty]], 2, FALSE) -> Adhoc Fees | C22: =VLOOKUP($A22, Rate[[SAP Code]:[Qty]], 3, FALSE) -> 1 | E22: =C22*D22 -> 0
A23: Disbursement | B23: =VLOOKUP(A23, Rate[[SAP Code]:[Qty]], 2, FALSE) -> Disbursement Fee | C23: =VLOOKUP($A23, Rate[[SAP Code]:[Qty]], 3, FALSE) -> 1 | E23: =C23*D23 -> 0
A24: 1200108 | B24: =VLOOKUP(A24, Rate[[SAP Code]:[Qty]], 2, FALSE) -> Labour - Labour Rate Weekday | C24: =VLOOKUP($A24, Rate[[SAP Code]:[Qty]], 3, FALSE) -> 110 | E24: =C24*D24 -> 0
A25: 1200109 | B25: =VLOOKUP(A25, Rate[[SAP Code]:[Qty]], 2, FALSE) -> API Management | C25: =VLOOKUP($A25, Rate[[SAP Code]:[Qty]], 3, FALSE) -> 180 | D25: 1 | E25: =C25*D25 -> 180
D27: Total | E27: =SUM(E2:E25) -> 1139.92

Sheet Errors
A1: Source | B1: Message
A2: Shipped SKU | B2: =_xlfn.IFNA(INDEX(Ship_SKU[Error],MATCH(TRUE,INDEX(Ship_SKU[Error]<>"",0),0)), "")
A3: Shipped Types | B3: =_xlfn.IFNA(INDEX(Ship_Type[Error],MATCH(TRUE,INDEX(Ship_Type[Error]<>"",0),0)), "")
A4: SKU Summary | B4: =_xlfn.IFNA(INDEX(SKU[Error],MATCH(TRUE,INDEX(SKU[Error]<>"",0),0)), "")
A5: Type Summary | B5: =_xlfn.IFNA(INDEX(Type[Error],MATCH(TRUE,INDEX(Type[Error]<>"",0),0)), "")
A6: Rates | B6: =_xlfn.IFNA(INDEX(Rate[Error],MATCH(TRUE,INDEX(Rate[Error]<>"",0),0)), "")
